[2024-03-08T16:51:24.352+0000] {taskinstance.py:1979} INFO - Dependencies all met for dep_context=non-requeueable deps ti=<TaskInstance: my_weekly_dag.execute_python_script scheduled__2024-03-01T00:00:00+00:00 [queued]>
[2024-03-08T16:51:24.359+0000] {taskinstance.py:1979} INFO - Dependencies all met for dep_context=requeueable deps ti=<TaskInstance: my_weekly_dag.execute_python_script scheduled__2024-03-01T00:00:00+00:00 [queued]>
[2024-03-08T16:51:24.359+0000] {taskinstance.py:2193} INFO - Starting attempt 1 of 2
[2024-03-08T16:51:24.371+0000] {taskinstance.py:2214} INFO - Executing <Task(PythonOperator): execute_python_script> on 2024-03-01 00:00:00+00:00
[2024-03-08T16:51:24.379+0000] {standard_task_runner.py:60} INFO - Started process 133 to run task
[2024-03-08T16:51:24.384+0000] {standard_task_runner.py:87} INFO - Running: ['***', 'tasks', 'run', 'my_weekly_dag', 'execute_python_script', 'scheduled__2024-03-01T00:00:00+00:00', '--job-id', '5', '--raw', '--subdir', 'DAGS_FOLDER/sample_dag.py', '--cfg-path', '/tmp/tmpisr7hhiu']
[2024-03-08T16:51:24.387+0000] {standard_task_runner.py:88} INFO - Job 5: Subtask execute_python_script
[2024-03-08T16:51:24.435+0000] {task_command.py:423} INFO - Running <TaskInstance: my_weekly_dag.execute_python_script scheduled__2024-03-01T00:00:00+00:00 [running]> on host 1782cbdcb8d0
[2024-03-08T16:51:24.500+0000] {taskinstance.py:2510} INFO - Exporting env vars: AIRFLOW_CTX_DAG_OWNER='***' AIRFLOW_CTX_DAG_ID='my_weekly_dag' AIRFLOW_CTX_TASK_ID='execute_python_script' AIRFLOW_CTX_EXECUTION_DATE='2024-03-01T00:00:00+00:00' AIRFLOW_CTX_TRY_NUMBER='1' AIRFLOW_CTX_DAG_RUN_ID='scheduled__2024-03-01T00:00:00+00:00'
[2024-03-08T16:51:24.505+0000] {taskinstance.py:2728} ERROR - Task failed with exception
Traceback (most recent call last):
  File "/home/airflow/.local/lib/python3.8/site-packages/airflow/models/taskinstance.py", line 444, in _execute_task
    result = _execute_callable(context=context, **execute_callable_kwargs)
  File "/home/airflow/.local/lib/python3.8/site-packages/airflow/models/taskinstance.py", line 414, in _execute_callable
    return execute_callable(context=context, **execute_callable_kwargs)
  File "/home/airflow/.local/lib/python3.8/site-packages/airflow/operators/python.py", line 200, in execute
    return_value = self.execute_callable()
  File "/home/airflow/.local/lib/python3.8/site-packages/airflow/operators/python.py", line 217, in execute_callable
    return self.python_callable(*self.op_args, **self.op_kwargs)
  File "/opt/airflow/dags/sample_dag.py", line 25, in run_python_script
    from scripts.my_script import my_python_function
ModuleNotFoundError: No module named 'scripts.my_script'
[2024-03-08T16:51:24.515+0000] {taskinstance.py:1149} INFO - Marking task as UP_FOR_RETRY. dag_id=my_weekly_dag, task_id=execute_python_script, execution_date=20240301T000000, start_date=20240308T165124, end_date=20240308T165124
[2024-03-08T16:51:24.527+0000] {standard_task_runner.py:107} ERROR - Failed to execute job 5 for task execute_python_script (No module named 'scripts.my_script'; 133)
[2024-03-08T16:51:24.557+0000] {local_task_job_runner.py:234} INFO - Task exited with return code 1
[2024-03-08T16:51:24.570+0000] {taskinstance.py:3309} INFO - 0 downstream tasks scheduled from follow-on schedule check
