[2024-03-08T21:16:55.443+0000] {taskinstance.py:1979} INFO - Dependencies all met for dep_context=non-requeueable deps ti=<TaskInstance: scraping_and_mongo_dag.scrape_data scheduled__2024-01-04T00:00:00+00:00 [queued]>
[2024-03-08T21:16:55.475+0000] {taskinstance.py:1979} INFO - Dependencies all met for dep_context=requeueable deps ti=<TaskInstance: scraping_and_mongo_dag.scrape_data scheduled__2024-01-04T00:00:00+00:00 [queued]>
[2024-03-08T21:16:55.476+0000] {taskinstance.py:2193} INFO - Starting attempt 1 of 2
[2024-03-08T21:16:55.565+0000] {taskinstance.py:2214} INFO - Executing <Task(PythonOperator): scrape_data> on 2024-01-04 00:00:00+00:00
[2024-03-08T21:16:55.601+0000] {standard_task_runner.py:60} INFO - Started process 705 to run task
[2024-03-08T21:16:55.729+0000] {standard_task_runner.py:87} INFO - Running: ['***', 'tasks', 'run', 'scraping_and_mongo_dag', 'scrape_data', 'scheduled__2024-01-04T00:00:00+00:00', '--job-id', '34', '--raw', '--subdir', 'DAGS_FOLDER/First_dag.py', '--cfg-path', '/tmp/tmpo43_n2g1']
[2024-03-08T21:16:55.774+0000] {standard_task_runner.py:88} INFO - Job 34: Subtask scrape_data
[2024-03-08T21:16:55.979+0000] {task_command.py:423} INFO - Running <TaskInstance: scraping_and_mongo_dag.scrape_data scheduled__2024-01-04T00:00:00+00:00 [running]> on host 976893b99e15
[2024-03-08T21:16:56.296+0000] {taskinstance.py:2510} INFO - Exporting env vars: AIRFLOW_CTX_DAG_OWNER='***' AIRFLOW_CTX_DAG_ID='scraping_and_mongo_dag' AIRFLOW_CTX_TASK_ID='scrape_data' AIRFLOW_CTX_EXECUTION_DATE='2024-01-04T00:00:00+00:00' AIRFLOW_CTX_TRY_NUMBER='1' AIRFLOW_CTX_DAG_RUN_ID='scheduled__2024-01-04T00:00:00+00:00'
[2024-03-08T21:16:56.303+0000] {taskinstance.py:2728} ERROR - Task failed with exception
Traceback (most recent call last):
  File "/home/airflow/.local/lib/python3.8/site-packages/airflow/models/taskinstance.py", line 444, in _execute_task
    result = _execute_callable(context=context, **execute_callable_kwargs)
  File "/home/airflow/.local/lib/python3.8/site-packages/airflow/models/taskinstance.py", line 414, in _execute_callable
    return execute_callable(context=context, **execute_callable_kwargs)
  File "/home/airflow/.local/lib/python3.8/site-packages/airflow/operators/python.py", line 200, in execute
    return_value = self.execute_callable()
  File "/home/airflow/.local/lib/python3.8/site-packages/airflow/operators/python.py", line 217, in execute_callable
    return self.python_callable(*self.op_args, **self.op_kwargs)
  File "/opt/airflow/dags/First_dag.py", line 24, in <lambda>
    python_callable=lambda: exec(open(python_script_path).read()),
FileNotFoundError: [Errno 2] No such file or directory: 'E:\\Python_DAG\\scripts\\First_scrapper.py'
[2024-03-08T21:16:56.334+0000] {taskinstance.py:1149} INFO - Marking task as UP_FOR_RETRY. dag_id=scraping_and_mongo_dag, task_id=scrape_data, execution_date=20240104T000000, start_date=20240308T211655, end_date=20240308T211656
[2024-03-08T21:16:56.379+0000] {standard_task_runner.py:107} ERROR - Failed to execute job 34 for task scrape_data ([Errno 2] No such file or directory: 'E:\\Python_DAG\\scripts\\First_scrapper.py'; 705)
[2024-03-08T21:16:56.437+0000] {local_task_job_runner.py:234} INFO - Task exited with return code 1
[2024-03-08T21:16:56.497+0000] {taskinstance.py:3309} INFO - 0 downstream tasks scheduled from follow-on schedule check
