[2024-03-08T21:21:59.087+0000] {taskinstance.py:1979} INFO - Dependencies all met for dep_context=non-requeueable deps ti=<TaskInstance: scraping_and_mongo_dag.scrape_data scheduled__2024-01-03T00:00:00+00:00 [queued]>
[2024-03-08T21:21:59.099+0000] {taskinstance.py:1979} INFO - Dependencies all met for dep_context=requeueable deps ti=<TaskInstance: scraping_and_mongo_dag.scrape_data scheduled__2024-01-03T00:00:00+00:00 [queued]>
[2024-03-08T21:21:59.100+0000] {taskinstance.py:2193} INFO - Starting attempt 2 of 2
[2024-03-08T21:21:59.121+0000] {taskinstance.py:2214} INFO - Executing <Task(PythonOperator): scrape_data> on 2024-01-03 00:00:00+00:00
[2024-03-08T21:21:59.130+0000] {standard_task_runner.py:60} INFO - Started process 832 to run task
[2024-03-08T21:21:59.136+0000] {standard_task_runner.py:87} INFO - Running: ['***', 'tasks', 'run', 'scraping_and_mongo_dag', 'scrape_data', 'scheduled__2024-01-03T00:00:00+00:00', '--job-id', '52', '--raw', '--subdir', 'DAGS_FOLDER/First_dag.py', '--cfg-path', '/tmp/tmps3382j3l']
[2024-03-08T21:21:59.145+0000] {standard_task_runner.py:88} INFO - Job 52: Subtask scrape_data
[2024-03-08T21:21:59.255+0000] {task_command.py:423} INFO - Running <TaskInstance: scraping_and_mongo_dag.scrape_data scheduled__2024-01-03T00:00:00+00:00 [running]> on host 976893b99e15
[2024-03-08T21:21:59.351+0000] {taskinstance.py:2510} INFO - Exporting env vars: AIRFLOW_CTX_DAG_OWNER='***' AIRFLOW_CTX_DAG_ID='scraping_and_mongo_dag' AIRFLOW_CTX_TASK_ID='scrape_data' AIRFLOW_CTX_EXECUTION_DATE='2024-01-03T00:00:00+00:00' AIRFLOW_CTX_TRY_NUMBER='2' AIRFLOW_CTX_DAG_RUN_ID='scheduled__2024-01-03T00:00:00+00:00'
[2024-03-08T21:21:59.354+0000] {taskinstance.py:2728} ERROR - Task failed with exception
Traceback (most recent call last):
  File "/home/airflow/.local/lib/python3.8/site-packages/airflow/models/taskinstance.py", line 444, in _execute_task
    result = _execute_callable(context=context, **execute_callable_kwargs)
  File "/home/airflow/.local/lib/python3.8/site-packages/airflow/models/taskinstance.py", line 414, in _execute_callable
    return execute_callable(context=context, **execute_callable_kwargs)
  File "/home/airflow/.local/lib/python3.8/site-packages/airflow/operators/python.py", line 200, in execute
    return_value = self.execute_callable()
  File "/home/airflow/.local/lib/python3.8/site-packages/airflow/operators/python.py", line 217, in execute_callable
    return self.python_callable(*self.op_args, **self.op_kwargs)
  File "/opt/airflow/dags/First_dag.py", line 24, in <lambda>
    python_callable=lambda: exec(open(python_script_path).read()),
FileNotFoundError: [Errno 2] No such file or directory: 'E:\\Python_DAG\\scripts\\First_scrapper.py'
[2024-03-08T21:21:59.367+0000] {taskinstance.py:1149} INFO - Marking task as FAILED. dag_id=scraping_and_mongo_dag, task_id=scrape_data, execution_date=20240103T000000, start_date=20240308T212159, end_date=20240308T212159
[2024-03-08T21:21:59.383+0000] {standard_task_runner.py:107} ERROR - Failed to execute job 52 for task scrape_data ([Errno 2] No such file or directory: 'E:\\Python_DAG\\scripts\\First_scrapper.py'; 832)
[2024-03-08T21:21:59.430+0000] {local_task_job_runner.py:234} INFO - Task exited with return code 1
[2024-03-08T21:21:59.537+0000] {taskinstance.py:3309} INFO - 0 downstream tasks scheduled from follow-on schedule check
